Workbook

Sheet Consumables
A2: Month | B2: Customer | C2: Sales (VAT 포함) | D2: Sales (VAT 제외) | E2: CM | F2: CM % | G2: Commission 15% | H2: 입금 내역 | I2: 입금일 | J2: 비고
A3: 5 | B3: 세흥인쇄 | C3: =D3*1.1 -> 1738000 | D3: 1580000 | E3: 192600 | F3: =E3/D3 -> 0.12189873 | G3: =E3*30% -> 57780 | H3: 입금되었음 | I3: 41851 | J3: 7/31 입금 57,708원
C4: =D4*1.1 -> 1738000 | D4: 1580000 | E4: 192600 | F4: =E4/D4 -> 0.12189873 | G4: =E4*30% -> 57780 | H4: .
A5: 6 | B5: 세흥인쇄 | C5: =D5*1.1 -> 2519000 | D5: 2290000 | E5: 456300 | F5: =E5/D5 -> 0.19925764 | G5: =E5*30% -> 136890 | H5: 입금되었음 | I5: 41874 | J5: 8/23 입금 136,890원
C6: =D6*1.1 -> 2519000 | D6: 2290000 | E6: 456300 | F6: =E6/D6 -> 0.19925764 | G6: =E6*30% -> 136890 | H6: .
A7: 7 | B7: 세흥인쇄 | C7: =D7*1.1 -> 6833750 | D7: 6212500 | E7: 1532500 | F7: =E7/D7 -> 0.24668008 | G7: =E7*30% -> 459750 | H7: 입금되었음 | I7: 41907 | J7: 9/25 입금 459,750원
B8: 정명인쇄 | C8: =D8*1.1 -> 2057000 | D8: 1870000 | E8: 332000 | F8: =E8/D8 -> 0.17754011 | G8: =E8*30% -> 99600 | H8: 입금되었음 | I8: 41938 | J8: 10/26 입금 755,610원
C9: =D9*1.1 -> 8890750 | D9: 8082500 | E9: 1864500 | F9: =E9/D9 -> 0.23068358 | G9: =E9*30% -> 559350 | H9: .
A10: 8 | B10: 세흥인쇄 | C10: =D10*1.1 -> 9880750 | D10: 8982500 | E10: 2186500 | F10: =E10/D10 -> 0.24341776 | G10: =E10*30% -> 655950 | H10: 입금되었음 | I10: 41938
B11: 일흥피앤피 | C11: =D11*1.1 -> 1131900 | D11: 1029000 | E11: 259000 | F11: =E11/D11 -> 0.25170068 | G11: =E11*30% -> 77700 | H11: 입금되었음 | I11: 11월 22일 | J11: 11/22 732,630원
C12: =D12*1.1 -> 11012650 | D12: 10011500 | E12: 2445500 | F12: =E12/D12 -> 0.24426909 | G12: =E12*30% -> 733650 | H12: .
A13: 9 | B13: 세흥인쇄 | C13: =D13*1.1 -> 6611000 | D13: 6010000 | E13: 1765500 | F13: =E13/D13 -> 0.2937604 | G13: =E13*30% -> 529650 | H13: 입금되었음 | I13: 11월 22일
B14: 덕수산업 | C14: =D14*1.1 -> 110000 | D14: 100000 | E14: 75000 | F14: =E14/D14 -> 0.75 | G14: =E14*30% -> 22500 | H14: 입금되었음 | I14: 12월 30일
C15: =D15*1.1 -> 6721000 | D15: 6110000 | E15: 1840500 | F15: =E15/D15 -> 0.3012275 | G15: =E15*30% -> 552150 | H15: .
A16: 10 | B16: 맥스타 | C16: =D16*1.1 -> 1100000 | D16: 1000000 | E16: 300000 | F16: =E16/D16 -> 0.3 | G16: =E16*30% -> 90000 | H16: 입금되었음 | I16: 11월 22일
B17: 부경인재 | C17: =D17*1.1 -> 198000 | D17: 180000 | E17: 36000 | F17: =E17/D17 -> 0.2 | G17: =E17*30% -> 10800 | H17: 입금되었음 | I17: 11월 22일
B18: 세흥인쇄 | C18: =D18*1.1 -> 8179600 | D18: 7436000 | E18: 1976500 | F18: =E18/D18 -> 0.26580151 | G18: =E18*30% -> 592950 | H18: 입금되었음 | I18: 12월 30일 | J18: 12/30 입금 890,550원
B19: 이펙피앤피 | C19: =D19*1.1 -> 642400 | D19: 584000 | E19: 81600 | F19: =E19/D19 -> 0.13972603 | G19: =E19*30% -> 24480 | H19: 입금되었음 | I19: 11월 22일
B20: 대하팩키지 | C20: =D20*1.1 -> 1375000 | D20: 1250000 | E20: 457000 | F20: =E20/D20 -> 0.3656 | G20: =E20*30% -> 137100 | H20: 입금되었음 | I20: 12월 30일
B21: 동양인재 | C21: =D21*1.1 -> 1650000 | D21: 1500000 | E21: 190000 | F21: =E21/D21 -> 0.12666667 | G21: =E21*30% -> 57000 | H21: 입금되었음 | I21: 12월 30일
C22: =SUM(C16:C21) -> 13145000 | D22: =SUM(D16:D21) -> 11950000 | E22: =SUM(E16:E21) -> 3041100 | F22: =E22/D22 -> 0.25448536 | G22: =SUM(G16:G21) -> 912330 | H22: .
A23: 11 | B23: 세흥인쇄 | C23: =D23*1.1 -> 13402400 | D23: 12184000 | E23: 3373500 | F23: =E23/D23 -> 0.27687951 | G23: =E23*30% -> 1012050 | H23: 입금되었음 | I23: 41663 | J23: 1/24 입금 1.194,900원
B24: 세영애드 | C24: =D24*1.1 -> 2596000 | D24: 2360000 | E24: 440000 | F24: =E24/D24 -> 0.18644068 | G24: =E24*30% -> 132000 | H24: 입금되었음 | I24: 41800
B25: 동양인재 | C25: =D25*1.1 -> 1485000 | D25: 1350000 | E25: 270000 | F25: =E25/D25 -> 0.2 | G25: =E25*30% -> 81000 | H25: 입금되었음 | I25: 12월 30일
B26: 삼영특수(차인수) | C26: =D26*1.1 -> 968000 | D26: 880000 | E26: 251700 | F26: =E26/D26 -> 0.28602273 | G26: =E26*30% -> 75510 | H26: 입금되었음 | I26: 41800
B27: 삼영특수(차인수) | C27: =D27*1.1 -> 4400000 | D27: 4000000 | E27: 1401600 | F27: =E27/D27 -> 0.3504 | G27: =E27*30% -> 420480 | H27: 입금되었음 | I27: 41800
B28: 우정인쇄 | C28: =D28*1.1 -> 440000 | D28: 400000 | E28: 92000 | F28: =E28/D28 -> 0.23 | G28: =E28*30% -> 27600 | H28: 입금되었음 | I28: HKR Commission
B29: 대일프린텍 | C29: =D29*1.1 -> 715000 | D29: 650000 | E29: 125000 | F29: =E29/D29 -> 0.19230769 | G29: =E29*30% -> 37500 | H29: 입금되었음 | I29: HKR Commission
C30: =SUM(C23:C29) -> 24006400 | D30: =SUM(D23:D29) -> 21824000 | E30: =SUM(E23:E29) -> 5953800 | F30: =E30/D30 -> 0.27280975 | H30: .
A31: 12 | B31: 세흥인쇄 | C31: =D31*1.1 -> 12310650 | D31: 11191500 | E31: 3378000 | F31: =E31/D31 -> 0.30183621 | G31: =E31*20% -> 675600 | H31: 입금되었음 | I31: 41703 | J31: 3/5 입금 1,177,804원
B32: 정명인쇄 | C32: =D32*1.1 -> 1611500 | D32: 1465000 | E32: 249500 | F32: =E32/D32 -> 0.17030717 | G32: =E32*30% -> 74850 | H32: 입금되었음 | I32: 41663
B33: 일흥피앤피 | C33: =D33*1.1 -> 1273800 | D33: 1158000 | E33: 343000 | F33: =E33/D33 -> 0.29620035 | G33: =E33*30% -> 102900 | H33: 입금되었음 | I33: 41730 | J33: 4/1 입금 207,092원 469,412-60,000(주차료) -202,320(연말정산)=207,092
B34: 대하팩키지 | C34: =D34*1.1 -> 1375000 | D34: 1250000 | E34: 457000 | F34: =E34/D34 -> 0.3656 | G34: =E34*30% -> 137100 | H34: 입금 확인요망
B35: 덕수산업 | C35: =D35*1.1 -> 2750000 | D35: 2500000 | E35: 659200 | F35: =E35/D35 -> 0.26368 | G35: =E35*20% -> 131840 | H35: 입금되었음 | I35: 41703
B36: 동양인재 | C36: =D36*1.1 -> 1980000 | D36: 1800000 | E36: 360000 | F36: =E36/D36 -> 0.2 | G36: =E36*30% -> 108000 | H36: 입금되었음 | I36: 41663
C37: =SUM(C31:C36) -> 21300950 | D37: =SUM(D31:D36) -> 19364500 | E37: =SUM(E31:E36) -> 5446700 | F37: =E37/D37 -> 0.28127243 | H37: .
A38: 2014. 1 | B38: 덕수산업 | C38: 2750000 | D38: 2500000 | E38: 659200 | F38: =E38/D38 -> 0.26368 | G38: =E38*20% -> 131840 | H38: 입금되었음 | I38: 41703
B39: 동양인재 | C39: 2277000 | D39: 2070000 | E39: 77000 | F39: =E39/D39 -> 0.037198068 | G39: =E39*20% -> 15400 | H39: 입금되었음 | I39: 41703
B40: 디자인부산 | C40: 748000 | D40: 680000 | E40: 162140 | F40: =E40/D40 -> 0.23844118 | G40: =E40*20% -> 32428 | H40: 입금되었음 | I40: 41703
B41: 세영애드 | C41: 1298000 | D41: 1180000 | E41: 220000 | F41: =E41/D41 -> 0.18644068 | G41: =E41*20% -> 44000 | H41: 입금되었음 | I41: 41703
...

Sheet Technotrans
A1: Month | B1: Customer | C1: Sales (VAT 포함) | D1: Sales (VAT 제외) | E1: CM | F1: CM % | G1: Commission 15% | H1: 입금 내역 | I1: 입금일
A2: 2014. 5 | B2: 세흥인쇄 | C2: 42900000 | D2: 39000000 | F2: =E2/D2 -> 0 | G2: =E2*30% -> 0
C3: =SUM(C2:C2) -> 42900000 | D3: =SUM(D2:D2) -> 39000000 | E3: =SUM(E2:E2) -> 0 | F3: =E3/D3 -> 0 | G3: =SUM(G2:G2) -> 0
A4: 2014. 7 | B4: 팩컴 AAP | C4: 2090000 | D4: 1900000 | E4: 500000 | F4: =E4/D4 -> 0.26315789 | G4: =E4*30% -> 150000
B5: 신창 디지털프린텍 | C5: 431200 | D5: 392000 | F5: =E5/D5 -> 0 | G5: =E5*30% -> 0
C6: =SUM(C4:C5) -> 2521200 | D6: =SUM(D4:D5) -> 2292000 | E6: =SUM(E4:E5) -> 500000 | F6: =E6/D6 -> 0.21815009 | G6: =SUM(G4:G5) -> 150000
A7: 2014. 10 | B7: 송운사 | C7: 9515000 | D7: 8650000 | F7: =E7/D7 -> 0 | G7: =E7*30% -> 0
C8: =SUM(C7) -> 9515000 | D8: =SUM(D7) -> 8650000 | E8: =SUM(E7) -> 0 | F8: =E8/D8 -> 0 | G8: =SUM(G6:G7) -> 150000
A9: 2015. 1 | B9: 상현원색 | C9: 3850000 | D9: 3500000 | F9: =E9/D9 -> 0 | G9: =E9*30% -> 0
C10: =SUM(C9:C9) -> 3850000 | D10: =SUM(D9:D9) -> 3500000 | E10: =SUM(E9:E9) -> 0 | F10: =E10/D10 -> 0 | G10: =SUM(G9:G9) -> 0
A11: 2015. 2 | B11: 아이피디 | C11: 1375000 | D11: 1250000 | F11: =E11/D11 -> 0 | G11: =E11*30% -> 0
C12: =SUM(C11) -> 1375000 | D12: =SUM(D11) -> 1250000 | E12: =SUM(E11) -> 0 | F12: =E12/D12 -> 0 | G12: =SUM(G10:G11) -> 0
A13: 2015. 4 | B13: 팩컴 AAP | C13: 2090000 | D13: 1900000 | E13: 789354 | F13: =E13/D13 -> 0.41544947 | G13: =E13*30% -> 236806.2
B14: 아이피디 | C14: 790900 | D14: 719000 | E14: 457622 | F14: =E14/D14 -> 0.6364701
B15: 재능인쇄 | C15: 28490000 | D15: 25900000 | F15: =E15/D15 -> 0
C16: =SUM(C13:C15) -> 31370900 | D16: =SUM(D13:D15) -> 28519000 | E16: =SUM(E13:E15) -> 1246976 | F16: =E16/D16 -> 0.043724394 | G16: =SUM(G13:G15) -> 236806.2
A17: 2015. 5 | B17: 삼원인쇄 | C17: 2090000 | D17: 1900000 | E17: 789354 | F17: =E17/D17 -> 0.41544947
B18: 덕수산업 | C18: 369600 | D18: 336000 | E18: 177712 | F18: =E18/D18 -> 0.52890476 | G18: =E18*30% -> 53313.6
C19: =SUM(C17:C18) -> 2459600 | D19: =SUM(D17:D18) -> 2236000 | E19: =SUM(E17:E18) -> 967066 | F19: =E19/D19 -> 0.43249821 | G19: =SUM(G17:G18) -> 53313.6
A20: 2015. 6 | B20: 신흥피앤피 | C20: 583000 | D20: 530000 | E20: 216000 | F20: =E20/D20 -> 0.40754717 | G20: =E20*30% -> 64800
B21: 퍼시픽패키지 | C21: 577500 | D21: 525000 | E21: 228000 | F21: =E21/D21 -> 0.43428571 | G21: =E21*30% -> 68400
B22: 퍼시픽패키지 | C22: 462000 | D22: 420000 | E22: 176500 | F22: =E22/D22 -> 0.4202381 | G22: =E22*30% -> 52950
B23: 국민피앤텍 | C23: 198000 | D23: 180000 | E23: 100856 | F23: =E23/D23 -> 0.56031111 | G23: =E23*30% -> 30256.8
C24: =SUM(C20:C23) -> 1820500 | D24: =SUM(D20:D23) -> 1655000 | E24: =SUM(E20:E23) -> 721356 | F24: =E24/D24 -> 0.43586465 | G24: =SUM(G20:G23) -> 216406.8
A25: 2015. 7 | B25: 보문특수칼라 | C25: 440000 | D25: 400000 | E25: 202140 | F25: =E25/D25 -> 0.50535 | G25: =E25*30% -> 60642
B26: 퍼시픽패키지 | C26: 1309000 | D26: 1190000 | E26: 413200 | F26: =E26/D26 -> 0.34722689 | G26: =E26*30% -> 123960
B27: 퍼시픽패키지 | C27: 577500 | D27: 525000 | E27: 228000 | F27: =E27/D27 -> 0.43428571 | G27: =E27*30% -> 68400
B28: 배원인쇄사 | C28: 297000 | D28: 270000 | E28: 151284 | F28: =E28/D28 -> 0.56031111 | G28: =E28*30% -> 45385.2
C29: =SUM(C25:C28) -> 2623500 | D29: =SUM(D25:D28) -> 2385000 | E29: =SUM(E25:E28) -> 994624 | F29: =E29/D29 -> 0.41703312 | G29: =SUM(G25:G28) -> 298387.2
A30: 2015. 8 | B30: 세종씨앤피 | C30: 165000 | D30: 150000 | E30: 51070 | F30: =E30/D30 -> 0.34046667 | G30: =E30*30% -> 15321
B31: 국민피앤텍 | C31: 4950000 | D31: 4500000 | E31: 1700000 | F31: =E31/D31 -> 0.37777778 | G31: =E31*30% -> 510000
C32: =SUM(C30:C31) -> 5115000 | D32: =SUM(D30:D31) -> 4650000 | E32: =SUM(E30:E31) -> 1751070 | F32: =E32/D32 -> 0.37657419 | G32: =SUM(G30:G31) -> 525321
A33: 2015. 9 | B33: 한빛테크 | C33: 1342000 | D33: 1220000 | E33: 451800 | F33: =E33/D33 -> 0.37032787 | G33: =E33*30% -> 135540
C34: =SUM(C33:C33) -> 1342000 | D34: =SUM(D33:D33) -> 1220000 | E34: =SUM(E33:E33) -> 451800 | F34: =E34/D34 -> 0.37032787 | G34: =SUM(G33:G33) -> 135540
A35: 2015. 10 | B35: 퍼시픽패키지 | C35: 577500 | D35: 525000 | E35: 228000 | F35: =E35/D35 -> 0.43428571 | G35: =E35*30% -> 68400
B36: 퍼시픽패키지 | C36: 435600 | D36: 396000 | E36: 263800 | F36: =E36/D36 -> 0.66616162 | G36: =E36*30% -> 79140
B37: ㈜에스제이씨성전 | C37: 2310000 | D37: 2100000 | E37: 516600 | F37: =E37/D37 -> 0.246 | G37: =E37*30% -> 154980
B38: 조일인쇄 | C38: 418000 | D38: 380000 | E38: 36000 | F38: =E38/D38 -> 0.094736842 | J38: * 박영용 이사
C39: =SUM(C35:C38) -> 3741100 | D39: =SUM(D35:D38) -> 3401000 | E39: =SUM(E35:E38) -> 1044400 | F39: =E39/D39 -> 0.30708615 | G39: =SUM(G35:G38) -> 302520
A40: 2015. 11 | B40: 퍼시픽패키지 | C40: 770000 | D40: 700000 | E40: 304000 | F40: =E40/D40 -> 0.43428571 | G40: =E40*30% -> 91200
...

Sheet GOSS
A1: Month | B1: Customer | C1: Sales (VAT 포함) | D1: Sales (VAT 제외) | E1: CM | F1: CM % | G1: Commission 2% | H1: 입금 내역 | I1: 입금일 | J1: 비고
A2: 2015. 7 | B2: 매일신문사 | C2: 2508000 | D2: 2280000 | E2: 620300 | F2: =E2/D2 -> 0.2720614
C3: =SUM(C2:C2) -> 2508000 | D3: =SUM(D2:D2) -> 2280000 | E3: =SUM(E2:E2) -> 620300 | F3: =E3/D3 -> 0.2720614 | G3: =SUM(G2:G2) -> 0
A4: 2015. 10 | B4: 신흥피앤피 | C4: 4400000 | D4: 4000000 | E4: 2073198.1 | F4: =E4/D4 -> 0.51829952
B5: 재능인쇄 | C5: 1980000 | D5: 1800000 | E5: 892000 | F5: =E5/D5 -> 0.49555556
B6: 교학사 | C6: 418000 | D6: 380000 | E6: 205120 | F6: =E6/D6 -> 0.53978947
C7: =SUM(C4:C6) -> 6798000 | D7: =SUM(D4:D6) -> 6180000 | E7: =SUM(E4:E6) -> 3170318.1 | F7: =E7/D7 -> 0.51299645 | G7: =SUM(G4:G6) -> 0
A8: 2015. 11 | B8: 교학사 | C8: 1166000 | D8: 1060000 | E8: 677120 | F8: =E8/D8 -> 0.63879245
B9: 프린피아 문발공장-임경영대리 | C9: 1694000 | D9: 1540000 | E9: 764720 | F9: =E9/D9 -> 0.49657143
B10: 프린피아 주안 -임경영 대리 | C10: 946000 | D10: 860000 | E10: 382000 | F10: =E10/D10 -> 0.44418605
C11: =SUM(C8:C10) -> 3806000 | D11: =SUM(D8:D10) -> 3460000 | E11: =SUM(E8:E10) -> 1823840 | F11: =E11/D11 -> 0.52712139 | G11: =SUM(G8:G10) -> 0
A12: 2015. 12 | B12: 재능인쇄 | C12: 570900 | D12: 519000 | E12: 231000 | F12: =E12/D12 -> 0.44508671
B13: 프린피아 문발공장-임경영대리 | C13: 409200 | D13: 372000 | E13: 102000 | F13: =E13/D13 -> 0.27419355
B14: 프린피아 파주- 임경영대리 | C14: 464200 | D14: 422000 | E14: 150000 | F14: =E14/D14 -> 0.35545024
B15: 신흥피앤피 | C15: 165000 | D15: 150000 | E15: 150000 | F15: =E15/D15 -> 1
B16: 팩컴 AAP | C16: 759000 | D16: 690000 | E16: 482000 | F16: =E16/D16 -> 0.69855072
B17: 한국하이델베르그 | C17: 880000 | D17: 800000 | E17: 320000 | F17: =E17/D17 -> 0.4
B18: 교학사 | C18: 418000 | D18: 380000 | E18: 205120 | F18: =E18/D18 -> 0.53978947
B19: 한국경제신문 | C19: 20680000 | D19: 18800000 | E19: 2100000 | F19: =E19/D19 -> 0.11170213
B20: 팩컴 AAP | C20: 440000 | D20: 400000 | E20: 207000 | F20: =E20/D20 -> 0.5175
B21: 신흥피앤피 | C21: 1485000 | D21: 1350000 | E21: 804000 | F21: =E21/D21 -> 0.59555556
B22: 프린피아 주안 -임경영 대리 | C22: 990000 | D22: 900000 | E22: 442500 | F22: =E22/D22 -> 0.49166667
B23: 프린피아 문발공장-임경영대리 | C23: 5060000 | D23: 4600000 | E23: 1792000 | F23: =E23/D23 -> 0.38956522
C24: =SUM(C12:C23) -> 32321300 | D24: =SUM(D12:D23) -> 29383000 | E24: =SUM(E12:E23) -> 6985620 | F24: =E24/D24 -> 0.23774359 | G24: =SUM(G12:G23) -> 0
A25: 2016. 1 | B25: 팩컴 AAP | C25: 9350000 | D25: 8500000 | E25: 4170000 | F25: =E25/D25 -> 0.49058824
B26: HnP(에치엔피) (구, 학원사) | C26: 11000000 | D26: 10000000 | E26: -1436000 | F26: =E26/D26 -> -0.1436
B27: 삼화인쇄 | C27: 990000 | D27: 900000 | E27: 275000 | F27: =E27/D27 -> 0.30555556
B28: 교학사 | C28: 264000 | D28: 240000 | E28: 188000 | F28: =E28/D28 -> 0.78333333
B29: 프린피아 주안 -임경영 대리 | C29: 3102000 | D29: 2820000 | E29: 1322500 | F29: =E29/D29 -> 0.46897163
B30: 매일경제(MBN) | C30: 1178650 | D30: 1071500 | E30: 1071500 | F30: =E30/D30 -> 1
C31: =SUM(C25:C30) -> 25884650 | D31: =SUM(D25:D30) -> 23531500 | E31: =SUM(E25:E30) -> 5591000 | F31: =E31/D31 -> 0.23759641 | G31: =SUM(G25:G30) -> 0
A32: 2016. 2 | B32: 매일경제(MBN) | C32: 6457000 | D32: 5870000 | E32: 1170000 | F32: =E32/D32 -> 0.19931857
B33: 삼화인쇄 | C33: 676500 | D33: 615000 | E33: 243000 | F33: =E33/D33 -> 0.39512195
B34: 보진재 | C34: 660000 | D34: 600000 | E34: 327600 | F34: =E34/D34 -> 0.546
B35: 신흥피앤피 | C35: 891000 | D35: 810000 | E35: 332000 | F35: =E35/D35 -> 0.40987654
B36: 재능인쇄 | C36: 1584000 | D36: 1440000 | E36: 713600 | F36: =E36/D36 -> 0.49555556
B37: 프린피아 주안 -임경영 대리 | C37: 500500 | D37: 455000 | E37: 171000 | F37: =E37/D37 -> 0.37582418
C38: =SUM(C32:C37) -> 10769000 | D38: =SUM(D32:D37) -> 9790000 | E38: =SUM(E32:E37) -> 2957200 | F38: =E38/D38 -> 0.30206333 | G38: =SUM(G32:G37) -> 0
A39: 2016. 3 | B39: 란쌍미디어 Lanxang Media | C39: 1650000 | D39: 1650000 | E39: 630000 | F39: =E39/D39 -> 0.38181818
B40: 재능인쇄 | C40: 2772000 | D40: 2520000 | E40: 1229000 | F40: =E40/D40 -> 0.48769841
...

Sheet 서비스
A1: Month | B1: Customer | C1: Sales (VAT 포함) | D1: Sales (VAT 제외) | E1: CM | F1: CM % | G1: Commission 2% | H1: 입금 내역 | I1: 입금일
A2: 2015. 11 | B2: 교학사 | C2: 275000 | D2: 250000 | E2: 250000 | F2: =E2/D2 -> 1
B3: 한국하이델베르그 | C3: 2640000 | D3: 2400000 | E3: 1200000 | F3: =E3/D3 -> 0.5
C4: =SUM(C2:C3) -> 2915000 | D4: =SUM(D2:D3) -> 2650000 | E4: =SUM(E2:E3) -> 1450000 | F4: =E4/D4 -> 0.54716981 | G4: =SUM(G2:G3) -> 0
A5: 2015. 12 | B5: 프린피아 문발공장-임경영대리 | C5: 409200 | D5: 372000 | E5: 102000 | F5: =E5/D5 -> 0.27419355
B6: 프린피아 파주- 임경영대리 | C6: 464200 | D6: 422000 | E6: 150000 | F6: =E6/D6 -> 0.35545024
B7: 신흥피앤피 | C7: 165000 | D7: 150000 | E7: 150000 | F7: =E7/D7 -> 1
B8: 팩컴 AAP | C8: 275000 | D8: 250000 | E8: 250000 | F8: =E8/D8 -> 1
B9: 한국하이델베르그 | C9: 880000 | D9: 800000 | E9: 320000 | F9: =E9/D9 -> 0.4
C10: =SUM(C5:C9) -> 2193400 | D10: =SUM(D5:D9) -> 1994000 | E10: =SUM(E5:E9) -> 972000 | F10: =E10/D10 -> 0.48746239 | G10: =SUM(G5:G9) -> 0
A11: 2016. 1 | B11: 신흥피앤피 | C11: 550000 | D11: 500000 | E11: 300000 | F11: =E11/D11 -> 0.6
C12: =SUM(C11:C11) -> 550000 | D12: =SUM(D11:D11) -> 500000 | E12: =SUM(E11:E11) -> 300000 | F12: =E12/D12 -> 0.6 | G12: =SUM(G11:G11) -> 0
A13: 2016. 3 | B13: 삼화인쇄 | C13: 1108800 | D13: 1008000 | E13: 300000 | F13: =E13/D13 -> 0.29761905
B14: 팩컴 AAP | C14: 605000 | D14: 550000 | E14: 550000 | F14: =E14/D14 -> 1
B15: 아이앤피 | C15: 385000 | D15: 350000 | E15: 350000 | F15: =E15/D15 -> 1
B16: 프린피아 문발공장-임경영대리 | C16: 165000 | D16: 150000 | E16: 150000 | F16: =E16/D16 -> 1
B17: ㈜ 대흥 | C17: 165000 | D17: 150000 | E17: 150000 | F17: =E17/D17 -> 1
C18: =SUM(C13:C17) -> 2428800 | D18: =SUM(D13:D17) -> 2208000 | E18: =SUM(E13:E17) -> 1500000 | F18: =E18/D18 -> 0.67934783 | G18: =SUM(G13:G17) -> 0
A19: 2016. 4 | B19: HKR (재능인쇄 서비스 비용) | C19: -2095500 | D19: -1905000 | E19: -1905000 | F19: =E19/D19 -> 1 | G19: * HKR 청구금액 for 재능인쇄 M600 서비스(이상훈 이사)
B20: 재능인쇄 | C20: 1375000 | D20: 1250000 | E20: 1250000 | F20: =E20/D20 -> 1 | G20: * GOSS M600 연간 서비스계약 (총 5백만원, 4회 분할) 1회
B21: 재능인쇄 | C21: 55000 | D21: 50000 | E21: 50000 | F21: =E21/D21 -> 1 | G21: * M600 서비스 야간출장비 100,000원을 2회 분할 발행
B22: 재능인쇄 | C22: 55000 | D22: 50000 | E22: 50000 | F22: =E22/D22 -> 1 | G22: * M600 서비스 야간출장비 100,000원을 2회 분할 발행
B23: 교학사 | C23: 605000 | D23: 550000 | E23: 550000 | F23: =E23/D23 -> 1
B24: 프린피아 문발공장-임경영대리 | C24: 1210000 | D24: 1100000 | E24: 1100000 | F24: =E24/D24 -> 1
C25: =SUM(C19:C24) -> 1204500 | D25: =SUM(D19:D24) -> 1095000 | E25: =SUM(E19:E24) -> 1095000 | F25: =E25/D25 -> 1 | G25: =SUM(G19:G24) -> 0
A26: 2016. 5 | B26: 프린피아 문발공장-임경영대리 | C26: 275000 | D26: 250000 | E26: 250000 | F26: =E26/D26 -> 1
C27: =SUM(C26:C26) -> 275000 | D27: =SUM(D26:D26) -> 250000 | E27: =SUM(E26:E26) -> 250000 | F27: =E27/D27 -> 1 | G27: =SUM(G26:G26) -> 0
A28: 2016. 6 | B28: 재능인쇄 | C28: 1375000 | D28: 1250000 | E28: 1250000 | F28: =E28/D28 -> 1 | G28: * GOSS M600 연간 서비스계약 (총 5백만원, 4회 분할) 2회
C29: =SUM(C28:C28) -> 1375000 | D29: =SUM(D28:D28) -> 1250000 | E29: =SUM(E28:E28) -> 1250000 | F29: =E29/D29 -> 1 | G29: =SUM(G28:G28) -> 0
A30: 2016. 8 | B30: 삼화인쇄 | C30: 959200 | D30: 872000 | E30: 0 | F30: =E30/D30 -> 0 | G30: * GOSS 본사 엔지니어 서비스 비용
B31: 재능인쇄 | C31: 1375000 | D31: 1250000 | E31: 1250000 | F31: =E31/D31 -> 1 | G31: * GOSS M600 연간 서비스계약 (총 5백만원, 4회 분할) 3회
B32: 교학사 | C32: 1992100 | D32: 1811000 | E32: 0 | F32: =E32/D32 -> 0 | G32: * GOSS 본사 엔지니어 서비스 비용
B33: 프린피아 주안 -임경영 대리 | C33: 706200 | D33: 642000 | E33: 0 | F33: =E33/D33 -> 0 | G33: * GOSS 본사 엔지니어 서비스 비용
C34: =SUM(C30:C33) -> 5032500 | D34: =SUM(D30:D33) -> 4575000 | E34: =SUM(E30:E33) -> 1250000 | F34: =E34/D34 -> 0.27322404 | G34: =SUM(G30:G33) -> 0
A35: 2016. 10 | B35: 재능인쇄 | C35: 1375000 | D35: 1250000 | E35: 1250000 | F35: =E35/D35 -> 1 | G35: * GOSS M600 연간 서비스계약 (총 5백만원, 4회 분할) 4회
C36: =SUM(C35:C35) -> 1375000 | D36: =SUM(D35:D35) -> 1250000 | E36: =SUM(E35:E35) -> 1250000 | F36: =E36/D36 -> 1 | G36: =SUM(G35:G35) -> 0
A37: 2016. 12 | B37: 보진재 | C37: 275000 | D37: 250000 | E37: 250000 | F37: =E37/D37 -> 1
B38: 신흥피앤피 | C38: 242000 | D38: 220000 | E38: 220000 | F38: =E38/D38 -> 1
C39: =SUM(C37:C38) -> 517000 | D39: =SUM(D37:D38) -> 470000 | E39: =SUM(E37:E38) -> 470000 | F39: =E39/D39 -> 1 | G39: =SUM(G37:G38) -> 0
A40: 2017. 1 | B40: 보진재 | C40: 165000 | D40: 150000 | E40: 150000 | F40: =E40/D40 -> 1
...

Sheet 2017
A1: Sales
B2: 2017
A3: Product | B3: 1 | C3: 2 | D3: 3 | E3: 4 | F3: 5 | G3: 6 | H3: 7 | I3: 8 | J3: 9 | K3: 10 | L3: 11 | M3: 12 | N3: TOTAL | O3: Portion
A4: Blanket | B4: 12905500 | C4: 9640000 | D4: 13889500 | E4: 14045000 | F4: =SUMIF(INDIRECT("Report!I3:I55"),A4,INDIRECT("Report!G3:G55")) -> 7740000 | G4: =SUMIF(INDIRECT("Report!I58:I119"),A4,INDIRECT("Report!G58:G119")) -> 12827500 | H4: =SUMIF(INDIRECT("Report!I120:I196"),A4,INDIRECT("Report!G120:G196")) -> 9295000 | I4: =SUMIF(INDIRECT("Report!I198:I264"),A4,INDIRECT("Report!G198:G264")) -> 10901000 | J4: =SUMIF(INDIRECT("Report!I266:I342"),A4,INDIRECT("Report!G266:G342")) -> 16287000 | K4: =SUMIF(INDIRECT("Report!I344:I407"),A4,INDIRECT("Report!G344:G407")) -> 4200000 | L4: =SUMIF(INDIRECT("Report!I409:I480"),A4,INDIRECT("Report!G409:G480")) -> 8690000 | M4: =SUMIF(INDIRECT("Report!I482:I565"),A4,INDIRECT("Report!G482:G565")) -> 10125000 | N4: =SUM(B4:M4) -> 130545500 | O4: =N4/$N$17 -> 0.10748405
A5: CTP | B5: 22394000 | C5: 11505000 | D5: 4270000 | E5: 7123000 | F5: =SUMIF(INDIRECT("Report!I3:I55"),A5,INDIRECT("Report!G3:G55")) -> 9358000 | G5: =SUMIF(INDIRECT("Report!I58:I120"),A5,INDIRECT("Report!G58:G120")) -> 8560000 | H5: =SUMIF(INDIRECT("Report!I120:I196"),A5,INDIRECT("Report!G120:G196")) -> 9460000 | I5: =SUMIF(INDIRECT("Report!I198:I264"),A5,INDIRECT("Report!G198:G264")) -> 4456000 | J5: =SUMIF(INDIRECT("Report!I266:I342"),A5,INDIRECT("Report!G266:G342")) -> 5368000 | K5: =SUMIF(INDIRECT("Report!I344:I407"),A5,INDIRECT("Report!G344:G407")) -> 4171000 | L5: =SUMIF(INDIRECT("Report!I409:I480"),A5,INDIRECT("Report!G409:G480")) -> 3147400 | M5: =SUMIF(INDIRECT("Report!I482:I565"),A5,INDIRECT("Report!G482:G565")) -> 4461000 | N5: =SUM(B5:M5) -> 94273400 | O5: =N5/$N$17 -> 0.077619583
A6: Film | B6: 4961000 | C6: 4961000 | D6: 5054000 | E6: 2434000 | F6: =SUMIF(INDIRECT("Report!I3:I55"),A6,INDIRECT("Report!G3:G55")) -> 5054000 | G6: =SUMIF(INDIRECT("Report!I58:I120"),A6,INDIRECT("Report!G58:G120")) -> 2527000 | H6: =SUMIF(INDIRECT("Report!I120:I196"),A6,INDIRECT("Report!G120:G196")) -> 4868000 | I6: =SUMIF(INDIRECT("Report!I198:I264"),A6,INDIRECT("Report!G198:G264")) -> 2434000 | J6: =SUMIF(INDIRECT("Report!I266:I342"),A6,INDIRECT("Report!G266:G342")) -> 2475000 | K6: =SUMIF(INDIRECT("Report!I344:I407"),A6,INDIRECT("Report!G344:G407")) -> 5043000 | L6: =SUMIF(INDIRECT("Report!I409:I480"),A6,INDIRECT("Report!G409:G480")) -> 2527000 | M6: =SUMIF(INDIRECT("Report!I482:I565"),A6,INDIRECT("Report!G482:G565")) -> 7488000 | N6: =SUM(B6:M6) -> 49826000 | O6: =N6/$N$17 -> 0.041024014
A7: Fount | B7: 1790000 | C7: 1665000 | D7: 4037500 | E7: 145000 | F7: =SUMIF(INDIRECT("Report!I3:I55"),A7,INDIRECT("Report!G3:G55")) -> 4037500 | G7: =SUMIF(INDIRECT("Report!I58:I120"),A7,INDIRECT("Report!G58:G120")) -> 2185000 | H7: =SUMIF(INDIRECT("Report!I120:I196"),A7,INDIRECT("Report!G120:G196")) -> 1687500 | I7: =SUMIF(INDIRECT("Report!I198:I264"),A7,INDIRECT("Report!G198:G264")) -> 1175000 | J7: =SUMIF(INDIRECT("Report!I266:I342"),A7,INDIRECT("Report!G266:G342")) -> 4577500 | L7: =SUMIF(INDIRECT("Report!I409:I480"),A7,INDIRECT("Report!G409:G480")) -> 4155000 | M7: =SUMIF(INDIRECT("Report!I482:I565"),A7,INDIRECT("Report!G482:G565")) -> 4717500 | N7: =SUM(B7:M7) -> 30172500 | O7: =N7/$N$17 -> 0.024842393
A8: GOSS | B8: 8910000 | C8: 36207000 | D8: 10970000 | E8: 13000000 | F8: =SUMIF(INDIRECT("Report!H3:H55"),A8,INDIRECT("Report!G3:G55")) -> 9210000 | G8: =SUMIF(INDIRECT("Report!H58:H120"),A8,INDIRECT("Report!G58:G120")) -> 6935000 | H8: =SUMIF(INDIRECT("Report!H120:H196"),A8,INDIRECT("Report!G120:G196")) -> 53520000 | I8: =SUMIF(INDIRECT("Report!H198:H264"),A8,INDIRECT("Report!G198:G264")) -> 18460000 | J8: =SUMIF(INDIRECT("Report!H266:H342"),A8,INDIRECT("Report!G266:G342")) -> 531000 | K8: =SUMIF(INDIRECT("Report!H344:H407"),A8,INDIRECT("Report!G344:G407")) -> 10210000 | L8: =SUMIF(INDIRECT("Report!H409:H480"),A8,INDIRECT("Report!G409:G480")) -> 10029000 | M8: =SUMIF(INDIRECT("Report!H482:H565"),A8,INDIRECT("Report!G482:G565")) -> 8995000 | N8: =SUM(B8:M8) -> 186977000 | O8: =N8/$N$17 -> 0.15394668
A9: Others | B9: 6624000 | C9: 31268000 | D9: 22656000 | E9: 45507000 | F9: =SUMIF(INDIRECT("Report!I3:I55"),A9,INDIRECT("Report!G3:G55")) -> 2890000 | G9: =SUMIF(INDIRECT("Report!I58:I120"),A9,INDIRECT("Report!G58:G120")) -> 8461000 | H9: =SUMIF(INDIRECT("Report!I120:I196"),A9,INDIRECT("Report!G120:G196"))+43000000 -> 49921000 | I9: =SUMIF(INDIRECT("Report!I198:I264"),A9,INDIRECT("Report!G198:G264")) -> 4274000 | J9: =SUMIF(INDIRECT("Report!I266:I342"),A9,INDIRECT("Report!G266:G342")) -> 32592000 | K9: =SUMIF(INDIRECT("Report!I344:I407"),A9,INDIRECT("Report!G344:G407")) -> 3568000 | L9: =SUMIF(INDIRECT("Report!I409:I480"),A9,INDIRECT("Report!G409:G480")) -> 48431904 | M9: =SUMIF(INDIRECT("Report!I482:I565"),A9,INDIRECT("Report!G482:G565")) -> 4922000 | N9: =SUM(B9:M9) -> 261114904 | O9: =N9/$N$17 -> 0.21498779
A10: Roller | B10: 7570000 | C10: 469000 | F10: =SUMIF(INDIRECT("Report!I3:I55"),A10,INDIRECT("Report!G3:G55")) -> 9790000 | G10: =SUMIF(INDIRECT("Report!I58:I120"),A10,INDIRECT("Report!G58:G120")) -> 1660000 | H10: =SUMIF(INDIRECT("Report!I120:I196"),A10,INDIRECT("Report!G120:G196")) -> 3280000 | I10: =SUMIF(INDIRECT("Report!I198:I264"),A10,INDIRECT("Report!G198:G264")) -> 264000 | J10: =SUMIF(INDIRECT("Report!I266:I342"),A10,INDIRECT("Report!G266:G342")) -> 7385000 | K10: =SUMIF(INDIRECT("Report!I344:I407"),A10,INDIRECT("Report!G344:G407")) -> 0 | L10: =SUMIF(INDIRECT("Report!I409:I480"),A10,INDIRECT("Report!G409:G480")) -> 0 | M10: =SUMIF(INDIRECT("Report!I482:I565"),A10,INDIRECT("Report!G482:G565")) -> 7760000 | N10: =SUM(B10:M10) -> 38178000 | O10: =N10/$N$17 -> 0.031433686
A11: Technotrans | B11: 11180000 | C11: 2282000 | D11: 1816000 | E11: 52376840 | F11: =(Technotrans!D130) -> 91842200 | G11: =SUMIF(INDIRECT("Report!h58:h120"),A11,INDIRECT("Report!G58:G120"))+36876560 -> 44676560 | H11: =SUMIF(INDIRECT("Report!H120:H196"),A11,INDIRECT("Report!G120:G196")) -> 580000 | I11: =SUMIF(INDIRECT("Report!H198:H264"),A11,INDIRECT("Report!G198:G264")) -> 5933000 | J11: =SUMIF(INDIRECT("Report!H266:H342"),A11,INDIRECT("Report!G266:G342")) -> 15319000 | K11: =SUMIF(INDIRECT("Report!H344:H407"),A11,INDIRECT("Report!G344:G407")) -> 925000 | L11: =SUMIF(INDIRECT("Report!H409:H480"),A11,INDIRECT("Report!G409:G480")) -> 2380000 | M11: =SUMIF(INDIRECT("Report!H482:H565"),A11,INDIRECT("Report!G482:G565")) -> 2325000 | N11: =SUM(B11:M11) -> 231635600 | O11: =N11/$N$17 -> 0.19071614
A12: Wash | B12: 6410000 | C12: 4106000 | D12: 4595000 | E12: 2689000 | F12: =SUMIF(INDIRECT("Report!I3:I55"),A12,INDIRECT("Report!G3:G55")) -> 5465500 | G12: =SUMIF(INDIRECT("Report!I58:I120"),A12,INDIRECT("Report!G58:G120")) -> 7523000 | H12: =SUMIF(INDIRECT("Report!I120:I196"),A12,INDIRECT("Report!G120:G196")) -> 3732500 | I12: =SUMIF(INDIRECT("Report!I198:I264"),A12,INDIRECT("Report!G198:G264")) -> 4081000 | J12: =SUMIF(INDIRECT("Report!I266:I342"),A12,INDIRECT("Report!G266:G342")) -> 4860000 | K12: =SUMIF(INDIRECT("Report!I344:I407"),A12,INDIRECT("Report!G344:G407")) -> 4779000 | L12: =SUMIF(INDIRECT("Report!I409:I480"),A12,INDIRECT("Report!G409:G480")) -> 6677000 | M12: =SUMIF(INDIRECT("Report!I482:I565"),A12,INDIRECT("Report!G482:G565")) -> 9771000 | N12: =SUM(B12:M12) -> 64689000 | O12: =N12/$N$17 -> 0.053261399
A13: 농도계 | B13: 0 | C13: 0 | D13: 0 | E13: 0 | F13: 0 | G13: 0 | H13: =SUMIF(INDIRECT("Report!I120:I196"),A13,INDIRECT("Report!G120:G196")) -> 0 | I13: 0 | J13: =SUMIF(INDIRECT("Report!I266:I342"),A13,INDIRECT("Report!J266:J342")) -> 0 | K13: =SUMIF(INDIRECT("Report!I344:I407"),A13,INDIRECT("Report!G344:G407")) -> 0 | L13: =SUMIF(INDIRECT("Report!I409:I480"),A13,INDIRECT("Report!G409:G480")) -> 0 | M13: =SUMIF(INDIRECT("Report!I482:I565"),A13,INDIRECT("Report!G482:G565")) -> 0 | N13: =SUM(B13:M13) -> 0 | O13: =N13/$N$17 -> 0
A14: Ink | B14: 0 | C14: 0 | D14: 0 | E14: 0 | F14: =SUMIF(INDIRECT("Report!I3:I55"),A14,INDIRECT("Report!G3:G55")) -> 723000 | G14: =SUMIF(INDIRECT("Report!I58:I120"),A14,INDIRECT("Report!G58:G120")) -> 13358800 | H14: =SUMIF(INDIRECT("Report!I120:I196"),A14,INDIRECT("Report!G120:G196")) -> 13559000 | I14: =SUMIF(INDIRECT("Report!I198:I264"),A14,INDIRECT("Report!G198:G264")) -> 9919000 | J14: =SUMIF(INDIRECT("Report!I266:I342"),A14,INDIRECT("Report!G266:G342")) -> 11371600 | K14: =SUMIF(INDIRECT("Report!I344:I407"),A14,INDIRECT("Report!G344:G407")) -> 9718800 | L14: =SUMIF(INDIRECT("Report!I409:I480"),A14,INDIRECT("Report!G409:G480")) -> 9482800 | M14: =SUMIF(INDIRECT("Report!I482:I565"),A14,INDIRECT("Report!G482:G565")) -> 9436000 | N14: =SUM(B14:M14) -> 77569000 | O14: =N14/$N$17 -> 0.06386609
A15: Service | B15: 150000 | C15: 7250000 | D15: 0 | E15: 1650000 | F15: =SUMIF(INDIRECT("Report!H3:H55"),A15,INDIRECT("Report!F3:F55")) -> 0 | G15: =SUMIF(INDIRECT("Report!h58:h120"),A15,INDIRECT("Report!F58:F120")) -> 1980000 | H15: =SUMIF(INDIRECT("Report!H120:H196"),A15,INDIRECT("Report!G120:G196")) -> 0 | I15: =SUMIF(INDIRECT("Report!H198:H264"),A15,INDIRECT("Report!G198:G264")) -> 17178000 | J15: =SUMIF(INDIRECT("Report!H266:H342"),A15,INDIRECT("Report!G266:G342")) -> 9538000 | K15: =SUMIF(INDIRECT("Report!H344:H407"),A15,INDIRECT("Report!G344:G407")) -> 1250000 | L15: =SUMIF(INDIRECT("Report!H409:H480"),A15,INDIRECT("Report!G409:G480")) -> 10330000 | M15: =SUMIF(INDIRECT("Report!H482:H565"),A15,INDIRECT("Report!G482:G565")) -> 250000 | N15: =SUM(B15:M15) -> 49576000 | O15: =N15/$N$17 -> 0.040818178
A16: Machine | L16: =SUMIF(INDIRECT("Report!I409:I480"),A16,INDIRECT("Report!G409:G480")) -> 240000000 | M16: =SUMIF(INDIRECT("Report!I482:I565"),A16,INDIRECT("Report!G482:G565")) -> 27400000 | N16: =SUM(B16:M16) -> 267400000 | O16: =N16/$N$17 -> 0.2201626
A17: 총합계(+VAT) | B17: =SUM(B4:B16)*1.1 -> 91183950 | C17: =SUM(C4:C16)*1.1 -> 1.202883e+08 | D17: =SUM(D4:D16)*1.1 -> 74016800 | E17: =SUM(E4:E16)*1.1 -> 152866824 | F17: =SUM(F4:F16)*1.1 -> 160721220 | G17: =SUM(G4:G16)*1.1 -> 1.2176325e+08 | H17: =SUM(H4:H16)*1.1 -> 164893300 | I17: =SUM(I4:I16)*1.1 -> 86982500 | ... M17: =SUM(M4:M16)*1.1 -> 1.0741555e+08 | N17: =SUM(N4:N15) -> 1214556904 | O17: =N17/$N$17 -> 1
A19: Margin
B20: 2017 | P20: 품목별
A21: Product | B21: 1 | C21: 2 | D21: 3 | E21: 4 | F21: 5 | G21: 6 | H21: 7 | I21: 8 | J21: 9 | K21: 10 | L21: 11 | M21: 12 | N21: TOTAL | O21: Portion | P21: Margin
A22: Blanket | B22: 3416500 | C22: 2287800 | D22: 3407500 | E22: 3424500 | F22: =SUMIF(INDIRECT("Report!I3:I55"),A22,INDIRECT("Report!J3:J55")) -> 1763500 | G22: =SUMIF(INDIRECT("Report!I58:I119"),A22,INDIRECT("Report!J58:J119")) -> 3290200 | H22: =SUMIF(INDIRECT("Report!I120:I196"),A22,INDIRECT("Report!J120:J196")) -> 2291000 | I22: =SUMIF(INDIRECT("Report!I198:I264"),A22,INDIRECT("Report!J198:J264")) -> 2371500 | J22: =SUMIF(INDIRECT("Report!I266:I342"),A22,INDIRECT("Report!J266:J342")) -> 3492500 | K22: =SUMIF(INDIRECT("Report!I344:I407"),A22,INDIRECT("Report!J344:J407")) -> 836000 | L22: =SUMIF(INDIRECT("Report!I409:I480"),A22,INDIRECT("Report!J409:J480")) -> 1934000 | M22: =SUMIF(INDIRECT("Report!I482:I565"),A22,INDIRECT("Report!J482:J565")) -> 2431800 | N22: =SUM(B22:M22) -> 30946800 | O22: =N22/$N$34 -> 0.069111686 | P22: =N22/N4 -> 0.23705758
A23: CTP | B23: 4546000 | C23: 2474000 | D23: 995000 | E23: 1967000 | F23: =SUMIF(INDIRECT("Report!I3:I55"),A23,INDIRECT("Report!J3:J55")) -> 2980000 | G23: =SUMIF(INDIRECT("Report!I58:I120"),A23,INDIRECT("Report!J58:J120")) -> 2730000 | H23: =SUMIF(INDIRECT("Report!I120:I196"),A23,INDIRECT("Report!J120:J196")) -> 3020000 | I23: =SUMIF(INDIRECT("Report!I198:I264"),A23,INDIRECT("Report!J198:J264")) -> 1085000 | J23: =SUMIF(INDIRECT("Report!I266:I342"),A23,INDIRECT("Report!J266:J342")) -> 1730000 | K23: =SUMIF(INDIRECT("Report!I344:I407"),A23,INDIRECT("Report!J344:J407")) -> 1355000 | L23: =SUMIF(INDIRECT("Report!I409:I480"),A23,INDIRECT("Report!J409:J480")) -> 758000 | M23: =SUMIF(INDIRECT("Report!I482:I565"),A23,INDIRECT("Report!J482:J565")) -> 1470000 | N23: =SUM(B23:M23) -> 25110000 | O23: =N23/$N$34 -> 0.0560767 | P23: =N23/N5 -> 0.26635297
A24: Film | B24: 1038560 | C24: 1038560 | D24: 1046640 | E24: 477860 | F24: =SUMIF(INDIRECT("Report!I3:I55"),A24,INDIRECT("Report!J3:J55")) -> 1021720 | G24: =SUMIF(INDIRECT("Report!I58:I120"),A24,INDIRECT("Report!J58:J120")) -> 510860 | H24: =SUMIF(INDIRECT("Report!I120:I196"),A24,INDIRECT("Report!J120:J196")) -> 980640 | I24: =SUMIF(INDIRECT("Report!I198:I264"),A24,INDIRECT("Report!J198:J264")) -> 477860 | J24: =SUMIF(INDIRECT("Report!I266:I342"),A24,INDIRECT("Report!J266:J342")) -> 493860 | K24: =SUMIF(INDIRECT("Report!I344:I407"),A24,INDIRECT("Report!J344:J407")) -> 1020720 | L24: =SUMIF(INDIRECT("Report!I409:I480"),A24,INDIRECT("Report!J409:J480")) -> 510860 | M24: =SUMIF(INDIRECT("Report!I482:I565"),A24,INDIRECT("Report!J482:J565")) -> 1499580 | N24: =SUM(B24:M24) -> 10117720 | O24: =N24/$N$34 -> 0.022595315 | P24: =N24/N6 -> 0.20306105
A25: Fount | B25: 922500 | C25: 585000 | D25: 1712500 | E25: 65000 | F25: =SUMIF(INDIRECT("Report!I3:I55"),A25,INDIRECT("Report!J3:J55")) -> 1712500 | G25: =SUMIF(INDIRECT("Report!I58:I120"),A25,INDIRECT("Report!J58:J120")) -> 1117500 | H25: =SUMIF(INDIRECT("Report!I120:I196"),A25,INDIRECT("Report!J120:J196")) -> 487500 | I25: =SUMIF(INDIRECT("Report!I198:I264"),A25,INDIRECT("Report!J198:J264")) -> 612500 | J25: =SUMIF(INDIRECT("Report!I266:I342"),A25,INDIRECT("Report!J266:J342")) -> 1972500 | K25: =SUMIF(INDIRECT("Report!I344:I407"),A25,INDIRECT("Report!J344:J407")) -> 612500 | L25: =SUMIF(INDIRECT("Report!I409:I480"),A25,INDIRECT("Report!J409:J480")) -> 1720000 | M25: =SUMIF(INDIRECT("Report!I482:I565"),A25,INDIRECT("Report!J482:J565")) -> 1882500 | N25: =SUM(B25:M25) -> 13402500 | O25: =N25/$N$34 -> 0.029931023 | P25: =N25/N7 -> 0.44419587
A26: GOSS | B26: 4250740 | C26: 17656413 | D26: 4691140 | E26: 7084000 | F26: =SUMIF(INDIRECT("Report!H3:H55"),A26,INDIRECT("Report!J3:J55")) -> 4024340 | G26: =SUMIF(INDIRECT("Report!h58:h120"),A26,INDIRECT("Report!J58:J120")) -> 6635000 | H26: =SUMIF(INDIRECT("Report!H120:H196"),A26,INDIRECT("Report!J120:J196")) -> 52854000 | I26: =SUMIF(INDIRECT("Report!H198:H264"),A26,INDIRECT("Report!J198:J264")) -> 15160000 | J26: =SUMIF(INDIRECT("Report!H266:H342"),A26,INDIRECT("Report!J266:J342")) -> 531000 | K26: =SUMIF(INDIRECT("Report!H344:H407"),A26,INDIRECT("Report!J344:J407")) -> 7959288.8 | L26: =SUMIF(INDIRECT("Report!H409:H480"),A26,INDIRECT("Report!J409:J480")) -> 7911000 | M26: =SUMIF(INDIRECT("Report!H482:H565"),A26,INDIRECT("Report!J482:J565")) -> 8005000 | N26: =SUM(B26:M26) -> 1.3676192e+08 | O26: =N26/$N$34 -> 0.30542243 | P26: =N26/N8 -> 0.73143714
A27: Others | B27: 2396000 | C27: 12634526 | D27: 5058500 | E27: 10324624 | F27: =SUMIF(INDIRECT("Report!I3:I55"),A27,INDIRECT("Report!J3:J55")) -> 850000 | G27: =SUMIF(INDIRECT("Report!I58:I120"),A27,INDIRECT("Report!J58:J120")) -> 1406200 | H27: =SUMIF(INDIRECT("Report!I120:I196"),A27,INDIRECT("Report!J120:J196"))+9708427 -> 11248027 | I27: =SUMIF(INDIRECT("Report!I198:I264"),A27,INDIRECT("Report!J198:J264")) -> 1198600 | J27: =SUMIF(INDIRECT("Report!I266:I342"),A27,INDIRECT("Report!J266:J342")) -> 1746000 | K27: =SUMIF(INDIRECT("Report!I344:I407"),A27,INDIRECT("Report!J344:J407")) -> 1118000 | L27: =SUMIF(INDIRECT("Report!I409:I480"),A27,INDIRECT("Report!J409:J480"))+SUMIF(INDIRECT("Report!H409:H480"),A27,INDIRECT("Report!J409:J480")) -> 59483344 | M27: =SUMIF(INDIRECT("Report!I482:I565"),A27,INDIRECT("Report!J482:J565")) -> 1405800 | N27: =SUM(B27:M27) -> 1.0886962e+08 | O27: =N27/$N$34 -> 0.24313218 | P27: =N27/N9 -> 0.41694143
A28: Roller | B28: 1860000 | C28: -757000 | F28: =SUMIF(INDIRECT("Report!I3:I55"),A28,INDIRECT("Report!J3:J55")) -> 2482094 | G28: =SUMIF(INDIRECT("Report!I58:I120"),A28,INDIRECT("Report!J58:J120")) -> 200000 | H28: =SUMIF(INDIRECT("Report!I120:I196"),A28,INDIRECT("Report!J120:J196")) -> 500000 | I28: =SUMIF(INDIRECT("Report!I198:I264"),A28,INDIRECT("Report!J198:J264")) -> 84000 | J28: =SUMIF(INDIRECT("Report!I266:I342"),A28,INDIRECT("Report!J266:J342")) -> 255000 | K28: =SUMIF(INDIRECT("Report!I344:I407"),A28,INDIRECT("Report!J344:J407")) -> 0 | L28: =SUMIF(INDIRECT("Report!I409:I480"),A28,INDIRECT("Report!J409:J480")) -> 0 | M28: =SUMIF(INDIRECT("Report!I482:I565"),A28,INDIRECT("Report!J482:J565")) -> 2000000 | N28: =SUM(B28:M28) -> 6624094 | O28: =N28/$N$34 -> 0.014793203 | P28: =N28/N10 -> 0.17350553
A29: Technotrans | B29: 3528562 | C29: 1064898.9 | D29: 742670 | E29: =(Technotrans!E124) -> 6544755.2 | F29: =Technotrans!E130 -> 11831906 | G29: =Technotrans!E138 -> 7551889.7 | H29: =SUMIF(INDIRECT("Report!H120:H196"),A29,INDIRECT("Report!J120:J196")) -> 310468 | I29: =SUMIF(INDIRECT("Report!H198:H264"),A29,INDIRECT("Report!J198:J264")) -> 5326373.5 | J29: =SUMIF(INDIRECT("Report!H266:H342"),A29,INDIRECT("Report!J266:J342")) -> 5748662 | K29: =SUMIF(INDIRECT("Report!H344:H407"),A29,INDIRECT("Report!J344:J407")) -> 812695 | L29: =SUMIF(INDIRECT("Report!H409:H480"),A29,INDIRECT("Report!J409:J480")) -> 2380000 | M29: =SUMIF(INDIRECT("Report!H482:H565"),A29,INDIRECT("Report!J482:J565")) -> 2325000 | N29: =SUM(B29:M29) -> 48167880 | O29: =N29/$N$34 -> 0.10757052 | P29: =N29/N11 -> 0.20794679
A30: Wash | B30: 1455000 | C30: 1066000 | D30: 905000 | E30: 674000 | F30: =SUMIF(INDIRECT("Report!I3:I55"),A30,INDIRECT("Report!J3:J55")) -> 1213500 | G30: =SUMIF(INDIRECT("Report!I58:I120"),A30,INDIRECT("Report!J58:J120")) -> 2234000 | H30: =SUMIF(INDIRECT("Report!I120:I196"),A30,INDIRECT("Report!J120:J196")) -> 872500 | I30: =SUMIF(INDIRECT("Report!I198:I264"),A30,INDIRECT("Report!J198:J264")) -> 872000 | J30: =SUMIF(INDIRECT("Report!I266:I342"),A30,INDIRECT("Report!J266:J342")) -> 1372000 | K30: =SUMIF(INDIRECT("Report!I344:I407"),A30,INDIRECT("Report!J344:J407")) -> 1104000 | L30: =SUMIF(INDIRECT("Report!I409:I480"),A30,INDIRECT("Report!J409:J480")) -> 2381000 | M30: =SUMIF(INDIRECT("Report!I482:I565"),A30,INDIRECT("Report!J482:J565")) -> 2605000 | N30: =SUM(B30:M30) -> 16754000 | O30: =N30/$N$34 -> 0.037415732 | P30: =N30/N12 -> 0.25899303
A31: 농도계 | B31: 0 | C31: 0 | D31: 0 | E31: 0 | F31: 0 | G31: 0 | H31: =SUMIF(INDIRECT("Report!I120:I196"),A31,INDIRECT("Report!J120:J196")) -> 0 | I31: 0 | J31: =SUMIF(INDIRECT("Report!I266:I342"),A31,INDIRECT("Report!J266:J342")) -> 0 | K31: =SUMIF(INDIRECT("Report!I344:I407"),A31,INDIRECT("Report!J344:J407")) -> 0 | L31: =SUMIF(INDIRECT("Report!I409:I480"),A31,INDIRECT("Report!J409:J480")) -> 0 | M31: =SUMIF(INDIRECT("Report!I482:I565"),A31,INDIRECT("Report!J482:J565")) -> 0 | N31: =SUM(B31:M31) -> 0 | O31: =N31/$N$34 -> 0 | P31: =N31/N13 -> #DIV/0!
A32: Ink | B32: 0 | C32: 0 | D32: 0 | E32: 0 | F32: =SUMIF(INDIRECT("Report!I3:I55"),A32,INDIRECT("Report!J3:J55")) -> 79700 | G32: =SUMIF(INDIRECT("Report!I58:I120"),A32,INDIRECT("Report!J58:J120")) -> 1383360 | H32: =SUMIF(INDIRECT("Report!I120:I196"),A32,INDIRECT("Report!J120:J196")) -> 1502120 | I32: =SUMIF(INDIRECT("Report!I198:I264"),A32,INDIRECT("Report!J198:J264")) -> 1058040 | J32: =SUMIF(INDIRECT("Report!I266:I342"),A32,INDIRECT("Report!J266:J342")) -> 1214080 | K32: =SUMIF(INDIRECT("Report!I344:I407"),A32,INDIRECT("Report!J344:J407")) -> 1054680 | L32: =SUMIF(INDIRECT("Report!I409:I480"),A32,INDIRECT("Report!J409:J480")) -> 1020760 | M32: =SUMIF(INDIRECT("Report!I482:I565"),A32,INDIRECT("Report!J482:J565")) -> 966280 | N32: =SUM(B32:M32) -> 8279020 | O32: =N32/$N$34 -> 0.018489053 | P32: =N32/N14 -> 0.10673104
A33: Service | B33: 150000 | C33: 7250000 | D33: 0 | E33: 1650000 | F33: =SUMIF(INDIRECT("Report!H3:H55"),A33,INDIRECT("Report!J3:J55")) -> 0 | G33: =SUMIF(INDIRECT("Report!h58:h120"),A33,INDIRECT("Report!J58:J120")) -> 1800000 | H33: =SUMIF(INDIRECT("Report!H120:H196"),A33,INDIRECT("Report!J120:J196")) -> 0 | I33: =I15 -> 17178000 | J33: =J15 -> 9538000 | K33: =SUMIF(INDIRECT("Report!H344:H407"),A33,INDIRECT("Report!J344:J407")) -> 1250000 | L33: =SUMIF(INDIRECT("Report!H409:H480"),A33,INDIRECT("Report!J409:J480")) -> 3680000 | M33: =SUMIF(INDIRECT("Report!H482:H565"),A33,INDIRECT("Report!J482:J565")) -> 250000 | N33: =SUM(B33:M33) -> 42746000 | O33: =N33/$N$34 -> 0.095462152 | P33: =N33/N15 -> 0.86223173
A34: Margin Total | B34: =SUM(B22:B33)*1.1 -> 25920248 | C34: =SUM(C22:C33)*1.1 -> 49830217 | D34: =SUM(D22:D33)*1.1 -> 20414845 | E34: =SUM(E22:E33)*1.1 -> 35432913 | F34: =SUM(F22:F33)*1.1 -> 30755186 | G34: =SUM(G22:G33)*1.1 -> 31744911 | H34: =SUM(H22:H33)*1.1 -> 81472880 | I34: =SUM(I22:I33)*1.1 -> 49966261 | ... M34: =SUM(M22:M33)*1.1 -> 27325056 | N34: =SUM(N22:N33) -> 4.4777956e+08 | O34: =SUM(O22:O33) -> 1
A35: 마진 % | B35: =B34/B17 -> 0.28426327 | C35: =C34/C17 -> 0.41425656 | D35: =D34/D17 -> 0.27581367 | E35: =E34/E17 -> 0.23178942 | F35: =F34/F17 -> 0.19135735 | G35: =G34/G17 -> 0.26071012 | H35: =H34/H17 -> 0.49409455 | I35: =I34/I17 -> 0.57444039 | ... N35: =N34/N17 -> 0.3686773
I37: YTD 12 months
B38: 합계 : Sales | F38: 합계 : CM
A39: Product | B39: 2013 | C39: 2014 | D39: 2015 | E39: 2016 | F39: 2013 | G39: 2014 | H39: 2015 | I39: 2016
A40: Blanket | B40: 21270000 | C40: 106683000 | D40: 169374500 | E40: 156041000 | F40: 4474380 | G40: 19408300 | H40: 33702400 | I40: 36698800
A41: CTP | D41: 16645000 | E41: 254899000 | H41: 2891300 | I41: 48134500
A42: Film | B42: 34629000 | C42: 53408500 | D42: 51778000 | E42: 48463000 | F42: 11489000 | G42: 14591500 | H42: 14188330 | I42: 10634320
...

Sheet Others
A1: Month | B1: Customer | C1: Sales (VAT 포함) | D1: Sales (VAT 제외) | E1: CM | F1: CM % | G1: 비고 | H1: 담당자
A2: 2017. 7 | B2: 재능(Ink & CTP) | C2: =SUMIFS(INDIRECT("Report!F100:F1000"),INDIRECT("Report!B100:B1000"),B2,INDIRECT("report!H100:H1000"),"Consums",INDIRECT("Report!L100:L1000"),"17.7") -> 25320900 | D2: =(C2/11*10) -> 23019000 | E2: =SUMIFS(INDIRECT("Report!J100:J1000"),INDIRECT("Report!B100:B1000"),B2,INDIRECT("report!H100:H1000"),"Consums",INDIRECT("Report!L100:L1000"),"17.7") -> 4522120 | F2: =E2/D2 -> 0.19645163
B3: 프린피아 문발 | C3: 47300000 | D3: =(C3/11*10) -> 43000000 | E3: 9708427 | F3: =E3/D3 -> 0.22577737 | G3: 판 절곡기
B4: 17,7 | C4: =SUM(C2:C3) -> 72620900 | D4: =SUM(D2:D3) -> 66019000 | E4: =SUM(E2:E3) -> 14230547 | F4: =E4/D4 -> 0.2155523
A5: 2017. 8 | B5: 재능(Ink & CTP) | C5: =SUMIFS(INDIRECT("Report!F100:F1000"),INDIRECT("Report!B100:B1000"),B5,INDIRECT("report!H100:H1000"),"Consums",INDIRECT("Report!L100:L1000"),"17.8") -> 15812500 | D5: =(C5/11*10) -> 14375000 | E5: =SUMIFS(INDIRECT("Report!J100:J1000"),INDIRECT("Report!B100:B1000"),B5,INDIRECT("report!H100:H1000"),"Consums",INDIRECT("Report!L100:L1000"),"17.8") -> 2143040 | F5: =E5/D5 -> 0.14908104 | G5: 잉크,판
C6: =SUM(C5) -> 15812500 | D6: =SUM(D5) -> 14375000 | E6: =SUM(E5) -> 2143040 | F6: =E6/D6 -> 0.14908104
A7: 2017. 9 | B7: 재능(Ink & CTP) | C7: =SUMIFS(INDIRECT("Report!F100:F1000"),INDIRECT("Report!B100:B1000"),B7,INDIRECT("report!H100:H1000"),"Consums",INDIRECT("Report!L100:L1000"),"17.9") -> 19865560 | D7: =(C7/11*10) -> 18059600 | E7: =SUMIFS(INDIRECT("Report!J100:J1000"),INDIRECT("Report!B100:B1000"),B7,INDIRECT("report!H100:H1000"),"Consums",INDIRECT("Report!L100:L1000"),"17.9") -> 3084080 | F7: =E7/D7 -> 0.17077233
B8: 재능 | C8: =SUMIFS(INDIRECT("Report!F100:F1000"),INDIRECT("Report!B100:B1000"),B8,INDIRECT("report!H100:H1000"),"Consums",INDIRECT("Report!L100:L1000"),"17.9") -> 29700000 | D8: =(C8/11*10) -> 27000000 | G8: OneVision Asura
C9: =SUM(C7:C8) -> 49565560 | D9: =SUM(D7:D8) -> 45059600
A10: 2017. 10 | B10: 재능(Ink & CTP) | C10: =SUMIFS(INDIRECT("Report!F100:F1000"),INDIRECT("Report!B100:B1000"),B10,INDIRECT("report!H100:H1000"),"Consums",INDIRECT("Report!L100:L1000"),"17.10") -> 15278780 | D10: =(C10/11*10) -> 13889800 | E10: =SUMIFS(INDIRECT("Report!J100:J1000"),INDIRECT("Report!B100:B1000"),B10,INDIRECT("report!H100:H1000"),"Consums",INDIRECT("Report!L100:L1000"),"17.10") -> 2409680 | F10: =E10/D10 -> 0.17348558
C11: =SUM(C10) -> 15278780 | D11: =SUM(D10) -> 13889800 | E11: =SUM(E10) -> 2409680 | F11: =E11/D11 -> 0.17348558
A12: 2017. 11 | B12: 재능(Ink & CTP) | C12: =SUMIFS(INDIRECT("Report!F100:F1000"),INDIRECT("Report!B100:B1000"),B12,INDIRECT("report!H100:H1000"),"Consums",INDIRECT("Report!L100:L1000"),"17.11") -> 13893220 | D12: =(C12/11*10) -> 12630200 | E12: =SUMIFS(INDIRECT("Report!J100:J1000"),INDIRECT("Report!B100:B1000"),B12,INDIRECT("report!H100:H1000"),"Consums",INDIRECT("Report!L100:L1000"),"17.11") -> 1778760 | F12: =E12/D12 -> 0.14083387
B13: 매일경제 | C13: =SUMIFS(INDIRECT("Report!F100:F1000"),INDIRECT("Report!B100:B1000"),B13,INDIRECT("report!H100:H1000"),"Others",INDIRECT("Report!L100:L1000"),"17.11") -> 2.707969e+08 | D13: =(C13/11*10) -> 2.46179e+08 | G13: 솔레노이드 밸브, CTP
C14: =SUM(C12:C13) -> 2.8469012e+08 | D14: =SUM(D13:D13) -> 2.46179e+08
A15: 2017. 12 | B15: 재능(Ink & CTP) | C15: =SUMIFS(INDIRECT("Report!F100:F1000"),INDIRECT("Report!B100:B1000"),B15,INDIRECT("report!H100:H1000"),"Others",INDIRECT("Report!L100:L1000"),"17.12") -> 15286700 | D15: =(C15/11*10) -> 13897000 | E15: =SUMIFS(INDIRECT("Report!J100:J1000"),INDIRECT("Report!B100:B1000"),B15,INDIRECT("report!H100:H1000"),"Others",INDIRECT("Report!L100:L1000"),"17.12") -> 2436280 | F15: =E15/D15 -> 0.17530978
B16: 지엔에스 | C16: =SUMIFS(INDIRECT("Report!F100:F1000"),INDIRECT("Report!B100:B1000"),B16,INDIRECT("report!H100:H1000"),"Others",INDIRECT("Report!L100:L1000"),"17.12") -> 30140000 | D16: =(C16/11*10) -> 27400000 | G16: 중고 CTP
C17: =SUM(C15:C16) -> 45426700 | D17: =SUM(D15:D16) -> 41297000
A18: 2018.1 | B18: 재능(Ink) | C18: =SUMIFS(INDIRECT("Report!F100:F1000"),INDIRECT("Report!B100:B1000"),B18,INDIRECT("report!H100:H1000"),"Others",INDIRECT("Report!L100:L1000"),"18.1") -> 9559000 | D18: =(C18/11*10) -> 8690000 | E18: =SUMIFS(INDIRECT("Report!J100:J1000"),INDIRECT("Report!B100:B1000"),B18,INDIRECT("report!H100:H1000"),"Others",INDIRECT("Report!L100:L1000"),"18.1") -> 976000 | F18: =E18/D18 -> 0.112313
B19: 재능(CTP) | C19: =SUMIFS(INDIRECT("Report!F100:F1000"),INDIRECT("Report!B100:B1000"),B19,INDIRECT("report!H100:H1000"),"Others",INDIRECT("Report!L100:L1000"),"18.1") -> 17954200 | D19: =(C19/11*10) -> 16322000 | E19: =SUMIFS(INDIRECT("Report!J100:J1000"),INDIRECT("Report!B100:B1000"),B19,INDIRECT("report!H100:H1000"),"Others",INDIRECT("Report!L100:L1000"),"18.1") -> 5230000 | F19: =E19/D19 -> 0.32042642
C20: =SUM(C18:C19) -> 27513200 | D20: =SUM(D18:D19) -> 25012000
A21: 2018.2 | B21: 재능(Ink) | C21: =SUMIFS(INDIRECT("Report!F100:F1000"),INDIRECT("Report!B100:B1000"),B21,INDIRECT("report!H100:H1000"),"Others",INDIRECT("Report!L100:L1000"),"18.2") -> 7832000 | D21: =(C21/11*10) -> 7120000 | E21: =SUMIFS(INDIRECT("Report!J100:J1000"),INDIRECT("Report!B100:B1000"),B21,INDIRECT("report!H100:H1000"),"Others",INDIRECT("Report!L100:L1000"),"18.2") -> 732000 | F21: =E21/D21 -> 0.10280899
B22: 재능(CTP) | C22: =SUMIFS(INDIRECT("Report!F100:F1000"),INDIRECT("Report!B100:B1000"),B22,INDIRECT("report!H100:H1000"),"Others",INDIRECT("Report!L100:L1000"),"18.2") -> 16700200 | D22: =(C22/11*10) -> 15182000 | E22: =SUMIFS(INDIRECT("Report!J100:J1000"),INDIRECT("Report!B100:B1000"),B22,INDIRECT("report!H100:H1000"),"Others",INDIRECT("Report!L100:L1000"),"18.2") -> 4870000 | F22: =E22/D22 -> 0.3207746
B23: 지엔에스 | C23: =SUMIFS(INDIRECT("Report!F100:F1000"),INDIRECT("Report!B100:B1000"),B23,INDIRECT("report!H100:H1000"),"Others",INDIRECT("Report!L100:L1000"),"18.2") -> 164450 | D23: =(C23/11*10) -> 149500 | E23: 149500 | F23: =E23/D23 -> 1
C24: =SUM(C21:C23) -> 24696650 | D24: =SUM(D21:D23) -> 22451500
A25: 2018.3 | B25: 재능(Ink) | C25: =SUMIFS(INDIRECT("Report!F100:F1000"),INDIRECT("Report!B100:B1000"),B25,INDIRECT("report!H100:H1000"),"Others",INDIRECT("Report!L100:L1000"),"18.3") -> 13915000 | D25: =(C25/11*10) -> 12650000 | E25: =SUMIFS(INDIRECT("Report!J100:J1000"),INDIRECT("Report!B100:B1000"),B25,INDIRECT("report!H100:H1000"),"Others",INDIRECT("Report!L100:L1000"),"18.3") -> 1136000 | F25: =E25/D25 -> 0.089802372
B26: 재능(CTP) | C26: =SUMIFS(INDIRECT("Report!F100:F1000"),INDIRECT("Report!B100:B1000"),B26,INDIRECT("report!H100:H1000"),"Others",INDIRECT("Report!L100:L1000"),"18.3") -> 40733000 | D26: =(C26/11*10) -> 37030000 | E26: =SUMIFS(INDIRECT("Report!J100:J1000"),INDIRECT("Report!B100:B1000"),B26,INDIRECT("report!H100:H1000"),"Others",INDIRECT("Report!L100:L1000"),"18.3") -> 12592000 | F26: =E26/D26 -> 0.34004861 | G26: 재고판 소진 포함
B27: 조선일보 | C27: =SUMIFS(INDIRECT("Report!F100:F1000"),INDIRECT("Report!B100:B1000"),B27,INDIRECT("report!H100:H1000"),"Others",INDIRECT("Report!L100:L1000"),"18.3") -> 6985000 | D27: =(C27/11*10) -> 6350000 | E27: =SUMIFS(INDIRECT("Report!J100:J1000"),INDIRECT("Report!B100:B1000"),B27,INDIRECT("report!H100:H1000"),"Others",INDIRECT("Report!L100:L1000"),"18.3") -> 1805000 | F27: =E27/D27 -> 0.28425197 | G27: QuadTech 기판
C28: =SUM(C25:C27) -> 61633000 | D28: =SUM(D25:D27) -> 56030000
A29: 2018.4 | B29: 재능(Ink) | C29: =SUMIFS(INDIRECT("Report!F100:F1000"),INDIRECT("Report!B100:B1000"),B29,INDIRECT("report!H100:H1000"),"Others",INDIRECT("Report!L100:L1000"),"18.4") -> 10310300 | D29: =(C29/11*10) -> 9373000 | E29: =SUMIFS(INDIRECT("Report!J100:J1000"),INDIRECT("Report!B100:B1000"),B29,INDIRECT("report!H100:H1000"),"Others",INDIRECT("Report!L100:L1000"),"18.4") -> 519000 | F29: =E29/D29 -> 0.055371813
B30: 재능(CTP) | C30: =SUMIFS(INDIRECT("Report!F100:F1000"),INDIRECT("Report!B100:B1000"),B30,INDIRECT("report!H100:H1000"),"Others",INDIRECT("Report!L100:L1000"),"18.4") -> 43948410 | D30: =(C30/11*10) -> 39953100 | E30: =SUMIFS(INDIRECT("Report!J100:J1000"),INDIRECT("Report!B100:B1000"),B30,INDIRECT("report!H100:H1000"),"Others",INDIRECT("Report!L100:L1000"),"18.4") -> 11806500 | F30: =E30/D30 -> 0.29550898 | G30: 재고판 소진 포함
C31: =SUM(C29:C30) -> 54258710 | D31: =SUM(D29:D30) -> 49326100
A32: 2018.5 | B32: 재능(Ink) | C32: =SUMIFS(INDIRECT("Report!F100:F1000"),INDIRECT("Report!B100:B1000"),B32,INDIRECT("report!H100:H1000"),"Others",INDIRECT("Report!L100:L1000"),"18.5") -> 16682600 | D32: =(C32/11*10) -> 15166000 | E32: =SUMIFS(INDIRECT("Report!J100:J1000"),INDIRECT("Report!B100:B1000"),B32,INDIRECT("report!H100:H1000"),"Others",INDIRECT("Report!L100:L1000"),"18.5") -> 1269000 | F32: =E32/D32 -> 0.083674008
B33: 재능(CTP) | C33: =SUMIFS(INDIRECT("Report!F100:F1000"),INDIRECT("Report!B100:B1000"),B33,INDIRECT("report!H100:H1000"),"Others",INDIRECT("Report!L100:L1000"),"18.5") -> 8350100 | D33: =(C33/11*10) -> 7591000 | E33: =SUMIFS(INDIRECT("Report!J100:J1000"),INDIRECT("Report!B100:B1000"),B33,INDIRECT("report!H100:H1000"),"Others",INDIRECT("Report!L100:L1000"),"18.5") -> 2435000 | F33: =E33/D33 -> 0.3207746
B34: 한국경제신문 | C34: =SUMIFS(INDIRECT("Report!F100:F1000"),INDIRECT("Report!B100:B1000"),B34,INDIRECT("report!H100:H1000"),"Others",INDIRECT("Report!L100:L1000"),"18.5") -> 10806576 | D34: =(C34/11*10) -> 9824160 | E34: =SUMIFS(INDIRECT("Report!J100:J1000"),INDIRECT("Report!B100:B1000"),B34,INDIRECT("report!H100:H1000"),"Others",INDIRECT("Report!L100:L1000"),"18.5") -> 3132534.8 | F34: =E34/D34 -> 0.31886032 | G34: 고스 부품
B35: 매일경제 | C35: =SUMIFS(INDIRECT("Report!F100:F1000"),INDIRECT("Report!B100:B1000"),B35,INDIRECT("report!H100:H1000"),"Others",INDIRECT("Report!L100:L1000"),"18.5") -> 9685500 | D35: =(C35/11*10) -> 8805000 | E35: =SUMIFS(INDIRECT("Report!J100:J1000"),INDIRECT("Report!B100:B1000"),B35,INDIRECT("report!H100:H1000"),"Others",INDIRECT("Report!L100:L1000"),"18.5") -> 2362950 | F35: =E35/D35 -> 0.26836457 | G35: 고스 부품
C36: =SUM(C32:C35) -> 45524776 | D36: =SUM(D32:D35) -> 41386160 | E36: =SUM(E32:E35) -> 9199484.8
A37: 2018.6 | B37: 재능(Ink) | C37: =SUMIFS(INDIRECT("Report!F100:F10000"),INDIRECT("Report!B100:B10000"),B37,INDIRECT("report!H100:H10000"),"Others",INDIRECT("Report!L100:L10000"),"18.6") -> 14440800 | D37: =(C37/11*10) -> 13128000 | E37: =SUMIFS(INDIRECT("Report!J100:J10000"),INDIRECT("Report!B100:B10000"),B37,INDIRECT("report!H100:H10000"),"Others",INDIRECT("Report!L100:L10000"),"18.6") -> 1114000 | F37: =E37/D37 -> 0.084856795
B38: 재능(CTP) | C38: =SUMIFS(INDIRECT("Report!F100:F10000"),INDIRECT("Report!B100:B10000"),B38,INDIRECT("report!H100:H10000"),"Others",INDIRECT("Report!L100:L10000"),"18.6") -> 17344800 | D38: =(C38/11*10) -> 15768000 | E38: =SUMIFS(INDIRECT("Report!J100:J10000"),INDIRECT("Report!B100:B10000"),B38,INDIRECT("report!H100:H10000"),"Others",INDIRECT("Report!L100:L10000"),"18.6") -> 5055000 | F38: =E38/D38 -> 0.320586
B39: 프린피아 주안 | C39: =SUMIFS(INDIRECT("Report!F100:F10000"),INDIRECT("Report!B100:B10000"),B39,INDIRECT("report!H100:H10000"),"Others",INDIRECT("Report!L100:L10000"),"18.6") -> 0 | D39: =(C39/11*10) -> 0 | E39: =SUMIFS(INDIRECT("Report!F100:F10000"),INDIRECT("Report!B100:B10000"),D39,INDIRECT("report!H100:H10000"),"Others",INDIRECT("Report!L100:L10000"),"18.6") -> 0 | F39: =E39/D39 -> #DIV/0! | G39: Beta.f 계약금
C40: =SUM(C37:C39) -> 31785600 | D40: =SUM(D37:D39) -> 28896000
...

Sheet Report
A1: Date | B1: Customer | C1: Item | D1: Qtt | E1: Price | F1: Sales(Tax) | G1: Sales(NonTax) | H1: Type1 | I1: Type2 | J1: Margin | K1: Margin (%) | L1: Month | M1: 비고 | N1: Date | O1: Order | P1: Item | Q1: Qtt | R1: Purchasing Price | S1: Total Purchase | T1: Total Purchase (Non Tax) | U1: 택배비 | V1: 비고 | W1: Margin (check) | X1: 수입
A2: 2017.5 | B2: 매출 | O2: 매입
A3: 170421 | B3: 재능 | C3: M-600 서비스 비용 | H3: Service | L3: 17.5 | M3: 계약시간 6시간 공제 | N3: =A3 -> 170421 | O3: Agfa | P3: =(C3) -> M-600 서비스 비용 | Q3: =D3 -> 0 | R3: 2740 | S3: =(R3*D3)*1.1 -> 0 | T3: =(R3*Q3) -> 0 | U3: =IF(J3=W3,"O", "X") -> O | W3: =(G3-T3) -> 0
A4: 170424 | B4: 재능 | C4: M-600 서비스 비용 | H4: Service | L4: 17.5 | M4: 계약시간 4시간 공제 | N4: =A4 -> 170424 | O4: Agfa | P4: =(C4) -> M-600 서비스 비용 | Q4: =D4 -> 0 | R4: 2740 | S4: =(R4*D4)*1.1 -> 0 | T4: =(R4*Q4) -> 0 | U4: =IF(J4=W4,"O", "X") -> O | W4: =(G4-T4) -> 0
A5: 170428 | B5: 세흥인쇄 | C5: Agfa Film(24inch) | D5: 2 | E5: 327000 | F5: =(E5*D5)*1.1 -> 719400 | G5: =(E5*D5) -> 654000 | H5: Consums | I5: Film | J5: =(G5-(VLOOKUP(C5,Price!B:D,3,FALSE)*D5)) -> 115800 | K5: =(J5/(G5/11*10)) -> 0.19477064 | L5: 17.5 | N5: =A5 -> 170428 | O5: Agfa | P5: =(C5) -> Agfa Film(24inch) | Q5: =D5 -> 2 | R5: 269100 | S5: =(R5*D5)*1.1 -> 592020 | T5: =(R5*Q5) -> 538200 | U5: =IF(J5=W5,"O", "X") -> O | W5: =(G5-T5) -> 115800
A6: 170428 | B6: 세흥인쇄 | C6: Agfa Film(28inch) | D6: 2 | E6: 401000 | F6: =(E6*D6)*1.1 -> 882200 | G6: =(E6*D6) -> 802000 | H6: Consums | I6: Film | J6: =(G6-(VLOOKUP(C6,Price!B:D,3,FALSE)*D6)) -> 174080 | K6: =(J6/(F6/11*10)) -> 0.21705736 | L6: 17.5 | N6: =A6 -> 170428 | O6: Agfa | P6: =(C6) -> Agfa Film(28inch) | Q6: =D6 -> 2 | R6: 313960 | S6: =(R6*D6)*1.1 -> 690712 | T6: =(R6*Q6) -> 627920 | U6: =IF(J6=W6,"O", "X") -> O | W6: =(G6-T6) -> 174080
A7: 170428 | B7: 세흥인쇄 | C7: Agfa Film(32inch) | D7: 2 | E7: 448000 | F7: =(E7*D7)*1.1 -> 985600 | G7: =(E7*D7) -> 896000 | H7: Consums | I7: Film | J7: =(G7-(VLOOKUP(C7,Price!B:D,3,FALSE)*D7)) -> 155980 | K7: =(J7/(F7/11*10)) -> 0.17408482 | L7: 17.5 | N7: =A7 -> 170428 | O7: Agfa | P7: =(C7) -> Agfa Film(32inch) | Q7: =D7 -> 2 | R7: 370010 | S7: =(R7*D7)*1.1 -> 814022 | T7: =(R7*Q7) -> 740020 | U7: =IF(J7=W7,"O", "X") -> O | W7: =(G7-T7) -> 155980
A8: 170428 | B8: 세흥인쇄 | C8: Agfa 현상액 G101C(10L) | D8: 2 | E8: 41000 | F8: =(E8*D8)*1.1 -> 90200 | G8: =(E8*D8) -> 82000 | H8: Consums | I8: Film | J8: =(G8-(VLOOKUP(C8,Price!B:D,3,FALSE)*D8)) -> 32000 | K8: =(J8/(F8/11*10)) -> 0.3902439 | L8: 17.5 | N8: =A8 -> 170428 | O8: Agfa | P8: =(C8) -> Agfa 현상액 G101C(10L) | Q8: =D8 -> 2 | R8: 25000 | S8: =(R8*D8)*1.1 -> 55000 | T8: =(R8*Q8) -> 50000 | U8: =IF(J8=W8,"O", "X") -> O | W8: =(G8-T8) -> 32000
A9: 170428 | B9: 세흥인쇄 | C9: Agfa 정착액 G333C(20L) | D9: 1 | E9: 93000 | F9: =(E9*D9)*1.1 -> 102300 | G9: =(E9*D9) -> 93000 | H9: Consums | I9: Film | J9: =(G9-(VLOOKUP(C9,Price!B:D,3,FALSE)*D9)) -> 33000 | K9: =(J9/(F9/11*10)) -> 0.35483871 | L9: 17.5 | N9: =A9 -> 170428 | O9: Agfa | P9: =(C9) -> Agfa 정착액 G333C(20L) | Q9: =D9 -> 1 | R9: 60000 | S9: =(R9*D9)*1.1 -> 66000 | T9: =(R9*Q9) -> 60000 | U9: =IF(J9=W9,"O", "X") -> O | W9: =(G9-T9) -> 33000
A10: 170502 | B10: 금강인쇄 | C10: Blanket(1050*840) | D10: 20 | E10: 100000 | F10: =(E10*D10)*1.1 -> 2200000 | G10: =(E10*D10) -> 2000000 | H10: Consums | I10: Blanket | J10: =(G10-(VLOOKUP(C10,Price!B:D,3,FALSE)*D10)) -> 390000 | K10: =(J10/(F10/11*10)) -> 0.195 | L10: 17.5 | N10: =A10 -> 170502 | O10: 동양잉크 | P10: =(C10) -> Blanket(1050*840) | Q10: =D10 -> 20 | R10: 80500 | S10: =(R10*D10)*1.1 -> 1771000 | T10: =(R10*Q10) -> 1610000 | U10: =IF(J10=W10,"O", "X") -> O | W10: =(G10-T10) -> 390000
A11: 170502 | B11: 재능 | C11: ENGAGE 27 900X570MM WE | D11: 1200 | E11: 3990 | F11: =(E11*D11)*1.1 -> 5266800 | G11: =(E11*D11) -> 4788000 | H11: Consums | I11: CTP | J11: =(G11-(VLOOKUP(C11,Price!B:D,3,FALSE)*D11)) -> 1500000 | K11: =(J11/(F11/11*10)) -> 0.31328321 | L11: 17.5 | N11: =A11 -> 170502 | O11: Agfa | P11: =(C11) -> ENGAGE 27 900X570MM WE | Q11: =D11 -> 1200 | R11: 2740 | S11: =(R11*D11)*1.1 -> 3616800 | T11: =(R11*Q11) -> 3288000 | U11: =IF(J11=W11,"O", "X") -> O | W11: =(G11-T11) -> 1500000
A12: 170509 | B12: 덕수 | C12: Blanket(1060*860) | D12: 10 | E12: 110000 | F12: =(E12*D12)*1.1 -> 1210000 | G12: =(E12*D12) -> 1100000 | H12: Consums | I12: Blanket | J12: =(G12-(VLOOKUP(C12,Price!B:D,3,FALSE)*D12)) -> 271000 | K12: =(J12/(F12/11*10)) -> 0.24636364 | L12: 17.5 | N12: =A12 -> 170509 | O12: 동양잉크 | P12: =(C12) -> Blanket(1060*860) | Q12: =D12 -> 10 | R12: 82900 | S12: =(R12*D12)*1.1 -> 911900 | T12: =(R12*Q12) -> 829000 | U12: =IF(J12=W12,"O", "X") -> O | W12: =(G12-T12) -> 271000
A13: 170509 | B13: 덕수 | C13: UV wash(20L) | D13: 5 | E13: 135000 | F13: =(E13*D13)*1.1 -> 742500 | G13: =(E13*D13) -> 675000 | H13: Consums | I13: Wash | J13: =(G13-(VLOOKUP(C13,Price!B:D,3,FALSE)*D13)) -> 125000 | K13: =(J13/(F13/11*10)) -> 0.18518519 | L13: 17.5 | N13: =A13 -> 170509 | O13: 붸처코리아 | P13: =(C13) -> UV wash(20L) | Q13: =D13 -> 5 | R13: 110000 | S13: =(R13*D13)*1.1 -> 605000 | T13: =(R13*Q13) -> 550000 | U13: =IF(J13=W13,"O", "X") -> O | W13: =(G13-T13) -> 125000
A14: 170510 | B14: 매일경제 | C14: Fount Web 551AF | D14: 10 | E14: 235000 | F14: =(E14*D14)*1.1 -> 2585000 | G14: =(E14*D14) -> 2350000 | H14: Consums | I14: Fount | J14: =(G14-(VLOOKUP(C14,Price!B:D,3,FALSE)*D14)) -> 1225000 | K14: =(J14/(F14/11*10)) -> 0.5212766 | L14: 17.5 | N14: =A14 -> 170510 | O14: 하이델베르그 | P14: =(C14) -> Fount Web 551AF | Q14: =D14 -> 10 | R14: 112500 | S14: =(R14*D14)*1.1 -> 1237500 | T14: =(R14*Q14) -> 1125000 | U14: =IF(J14=W14,"O", "X") -> O | W14: =(G14-T14) -> 1225000
A15: 170511 | B15: 대일프린텍 | C15: 고무사카 회색 | D15: 100 | E15: 500 | F15: =(E15*D15)*1.1 -> 55000 | G15: =(E15*D15) -> 50000 | H15: Consums | I15: Others | J15: =(G15-(VLOOKUP(C15,Price!B:D,3,FALSE)*D15)) -> 18000 | K15: =(J15/(F15/11*10)) -> 0.36 | L15: 17.5 | N15: =A15 -> 170511 | O15: 하이델베르그 | P15: =(C15) -> 고무사카 회색 | Q15: =D15 -> 100 | R15: 320 | S15: =(R15*D15)*1.1 -> 35200 | T15: =(R15*Q15) -> 32000 | U15: =IF(J15=W15,"O", "X") -> O | W15: =(G15-T15) -> 18000
A16: 170511 | B16: 대일프린텍 | C16: 고무사카 빨간색 | D16: 100 | E16: 500 | F16: =(E16*D16)*1.1 -> 55000 | G16: =(E16*D16) -> 50000 | H16: Consums | I16: Others | J16: =(G16-(VLOOKUP(C16,Price!B:D,3,FALSE)*D16)) -> 18000 | K16: =(J16/(F16/11*10)) -> 0.36 | L16: 17.5 | N16: =A16 -> 170511 | O16: 하이델베르그 | P16: =(C16) -> 고무사카 빨간색 | Q16: =D16 -> 100 | R16: 320 | S16: =(R16*D16)*1.1 -> 35200 | T16: =(R16*Q16) -> 32000 | U16: =IF(J16=W16,"O", "X") -> O | W16: =(G16-T16) -> 18000
A17: 170511 | B17: 팩컴 AAP | C17: 삼각판 코 | D17: 1 | E17: 5400000 | F17: =(E17*D17)*1.1 -> 5940000 | G17: =(E17*D17) -> 5400000 | H17: Goss | J17: =(G17-(VLOOKUP(C17,Price!B:D,3,FALSE)*D17)) -> 2221350 | K17: =(J17/(F17/11*10)) -> 0.41136111 | L17: 17.5 | N17: =A17 -> 170511 | O17: Goss | P17: =(C17) -> 삼각판 코 | Q17: =D17 -> 1 | R17: 3178650 | S17: =(R17*D17)*1.1 -> 3496515 | T17: =(R17*Q17) -> 3178650 | U17: =IF(J17=W17,"O", "X") -> O | W17: =(G17-T17) -> 2221350
A18: 170511 | B18: HnP | C18: 스트리퍼 | D18: 50 | E18: 12000 | F18: =(E18*D18)*1.1 -> 660000 | G18: =(E18*D18) -> 600000 | H18: Goss | J18: =(G18-(VLOOKUP(C18,Price!B:D,3,FALSE)*D18)) -> 150000 | K18: =(J18/(F18/11*10)) -> 0.25 | L18: 17.5 | N18: =A18 -> 170511 | O18: Goss | P18: =(C18) -> 스트리퍼 | Q18: =D18 -> 50 | R18: 6320 | S18: =(R18*D18)*1.1 -> 347600 | T18: =(R18*Q18) -> 316000 | U18: =IF(J18=W18,"O", "X") -> X | W18: =(G18-T18) -> 284000
A19: 170511 | B19: 프린피아 파주 | C19: 샤프트 잠금장치 | D19: 1 | E19: 850000 | F19: =(E19*D19)*1.1 -> 935000 | G19: =(E19*D19) -> 850000 | H19: Goss | J19: =(G19-(VLOOKUP(C19,Price!B:D,3,FALSE)*D19)) -> 423630 | K19: =(J19/(F19/11*10)) -> 0.49838824 | L19: 17.5 | N19: =A19 -> 170511 | O19: Goss | P19: =(C19) -> 샤프트 잠금장치 | Q19: =D19 -> 1 | R19: 426370 | S19: =(R19*D19)*1.1 -> 469007 | T19: =(R19*Q19) -> 426370 | U19: =IF(J19=W19,"O", "X") -> O | W19: =(G19-T19) -> 423630
